<?xml version="1.0"?>
<robot name="dribot_wheel" xmlns:xacro="http://ros.org/wiki/xacro">

  <xacro:macro name="wheel" params="prefix x_pos y_pos">
    <link name="${prefix}_link">
      <visual>
        <origin xyz="0 0 0" rpy="${pi/2} 0 0"/>
        <geometry>
            <cylinder radius="${wheel_radius}" length="${wheel_width}"/>
        </geometry>
      </visual>

      <collision>
        <origin xyz="0 0 0" rpy="${pi/2} 0 0"/>
        <geometry>
          <cylinder radius="${wheel_radius}" length="${wheel_width}"/>
        </geometry>
      </collision>

      <xacro:cylinder_inertia m="0.5" r="${wheel_radius}" h="${wheel_width}" roll="${pi/2}"/>
    </link>

    <joint name="${prefix}_joint" type="continuous">
      <parent link="base_link"/>
      <child link="${prefix}_link"/>
      <origin xyz="${x_pos} ${y_pos} ${-wheel_zoff}" rpy="0 0 0"/>
      <axis xyz="0 1 0"/>
    </joint>

    <gazebo reference="${prefix}_link">
      <mu1 value="0.50"/>
      <mu2 value="3.0"/>
      <kp  value="10000000.0" />
      <kd  value="100.0" />
      <fdir1 value="0 0 1"/>
      <material>Gazebo/Black</material>
    </gazebo>
  </xacro:macro>

</robot>
